<?xml version="1.0" ?>
<!-- =================================================================================== -->
<!-- |    This document was autogenerated by xacro from quadrobot_description_sim.xacro | -->
<!-- |    EDITING THIS FILE BY HAND IS NOT RECOMMENDED                                 | -->
<!-- =================================================================================== -->
<robot name="quadrobot">
  <material name="black">
    <color rgba="0.0 0.0 0.0 1.0"/>
  </material>
  <material name="blue">
    <color rgba="0.0 0.0 0.8 1.0"/>
  </material>
  <material name="green">
    <color rgba="0.0 0.8 0.0 1.0"/>
  </material>
  <material name="grey">
    <color rgba="0.2 0.2 0.2 1.0"/>
  </material>
  <material name="silver">
    <color rgba="0.9137254901960784 0.9137254901960784 0.8470588235294118 1.0"/>
  </material>
  <material name="orange">
    <color rgba="1.0 0.4235294117647059 0.0392156862745098 1.0"/>
  </material>
  <material name="brown">
    <color rgba="0.8705882352941177 0.8117647058823529 0.7647058823529411 1.0"/>
  </material>
  <material name="white_gray">
    <color rgba="0.8235294117647058 0.8235294117647058 0.8235294117647058 1.0"/>
  </material>
  <material name="gold">
    <color rgba="0.8117647058823529 0.6784313725490196 0.30196078431372547 1.0"/>
  </material>
  <material name="white_blue">
    <color rgba="0.4627450980392157 0.8 0.9921568627450981 1.0"/>
  </material>
  <material name="white_black">
    <color rgba="0.49411764705882355 0.49411764705882355 0.49411764705882355 1.0"/>
  </material>
  <material name="red">
    <color rgba="0.8 0.0 0.0 1.0"/>
  </material>
  <material name="white">
    <color rgba="1.0 1.0 1.0 1.0"/>
  </material>
  <link name="base_link">
    <inertial>
      <origin rpy="0 0 0" xyz="0.0 0.0 0.0"/>
      <mass value="0.00001"/>
      <inertia ixx="0.0" ixy="0.0" ixz="0.0" iyy="0.0" iyz="0.0" izz="0.0"/>
    </inertial>
  </link>
  <joint name="base_joint" type="fixed">
    <parent link="base_link"/>
    <child link="torso"/>
    <origin rpy="0 0 0" xyz="0 0 0"/>
  </joint>
  <!-- Torso -->
  <link name="torso">
    <visual>
      <geometry>
        <!-- <box size="${torso_length} ${torso_width} ${torso_heigth}"/> -->
        <mesh filename="meshes/body.stl" scale="1 1 1"/>
      </geometry>
      <origin rpy="0 0 0" xyz="0 0 0"/>
      <material name="silver"/>
    </visual>
    <collision>
      <geometry>
        <mesh filename="meshes/body.stl" scale="1 1 1"/>
        <!-- <mesh filename="meshes/torso.stl" scale="1 1 1"/> -->
      </geometry>
    </collision>
    <inertial>
      <origin rpy="0 0 0" xyz="0.0 0.0 0.0"/>
      <mass value="6.487"/>
      <inertia ixx="0.035393221" ixy="8.79e-06" ixz="0.0" iyy="0.084808187" iyz="0.0" izz="0.11312557"/>
    </inertial>
    <contact>
      <lateral_friction value="1"/>
    </contact>
  </link>
  <!-- Shoulder -->
  <joint name="shoulder_joint_R1" type="revolute">
    <parent link="torso"/>
    <child link="shoulder_R1"/>
    <origin rpy="0.0 1.5707963267948966 0.0" xyz="0.1965 -0.093 0"/>
    <axis xyz="0 0 -1"/>
    <dynamics damping="0.0" friction="0.0"/>
    <limit effort="2000" lower="2.6179938779914944" upper="-2.6179938779914944" velocity="0.05"/>
  </joint>
  <link name="shoulder_R1">
    <visual>
      <origin rpy="0 0 1.57" xyz="0 0 0"/>
      <geometry>
        <mesh filename="meshes/joint2.stl" scale="1 1 1"/>
      </geometry>
      <material name="white_blue"/>
    </visual>
    <collision>
      <origin rpy="0 0 1.57" xyz="0 0 0"/>
      <geometry>
        <mesh filename="meshes/joint2.stl" scale="1 1 1"/>
      </geometry>
    </collision>
    <inertial>
      <origin rpy="0 0 1.57" xyz="-2.2e-05 0.031173 0.057268"/>
      <mass value="0.733"/>
      <inertia ixx="0.00067621" ixy="3.8e-07" ixz="1.08e-07" iyy="0.000621118" iyz="-6.7409e-05" izz="0.000597825"/>
    </inertial>
    <contact>
      <lateral_friction value="1"/>
    </contact>
  </link>
  <!-- Hip-->
  <joint name="hip_joint_R1" type="revolute">
    <parent link="shoulder_R1"/>
    <child link="hip_R1"/>
    <origin rpy="0 -1.57 1.57" xyz="0 0.0025 0.060502"/>
    <axis xyz="0 0 -1"/>
    <dynamics damping="0.0" friction="0.0"/>
    <limit effort="2000" lower="2.6179938779914944" upper="-2.6179938779914944" velocity="0.05"/>
  </joint>
  <link name="hip_R1">
    <visual>
      <origin rpy="0 0 0" xyz="0 0 0"/>
      <geometry>
        <!-- <box size="0.202 0.05 0.03"/> -->
        <mesh filename="meshes/joint3.stl" scale="1 1 1"/>
      </geometry>
      <material name="silver"/>
    </visual>
    <collision>
      <geometry>
        <mesh filename="meshes/joint3.stl" scale="1 1 1"/>
      </geometry>
    </collision>
    <inertial>
      <origin rpy="0 0 0" xyz="0.022129 -0.00016 0.062823"/>
      <mass value="1.018"/>
      <inertia ixx="0.001081737" ixy="-2.78e-07" ixz="-0.000623088" iyy="0.003343252" iyz="-5e-07" izz="0.00299894"/>
    </inertial>
    <contact>
      <lateral_friction value="1"/>
    </contact>
  </link>
  <!-- Knee -->
  <joint name="knee_joint_R1" type="revolute">
    <parent link="hip_R1"/>
    <child link="knee_R1"/>
    <origin rpy="0 0 1.57" xyz="0.202 0 0.093"/>
    <axis xyz="0 0 -1"/>
    <dynamics damping="0.0" friction="0.0"/>
    <limit effort="2000" lower="-2.6179938779914944" upper="2.6179938779914944" velocity="0.05"/>
  </joint>
  <link name="knee_R1">
    <visual>
      <origin rpy="0 0 0" xyz="0 0 0"/>
      <geometry>
        <!-- <sphere radius="0.04"/> -->
        <mesh filename="meshes/joint4.stl" scale="1 1 1"/>
      </geometry>
      <material name="white_blue"/>
    </visual>
    <collision>
      <geometry>
        <mesh filename="meshes/joint4.stl" scale="1 1 1"/>
      </geometry>
    </collision>
    <inertial>
      <origin rpy="0 0 0" xyz="0.0 -0.055891 0.0"/>
      <mass value="0.195"/>
      <inertia ixx="0.000821112" ixy="0.0" ixz="0.0" iyy="3.9652e-05" iyz="0.0" izz="0.000838157"/>
    </inertial>
    <contact>
      <lateral_friction value="1"/>
    </contact>
  </link>
  <!-- End Effector-->
  <joint name="ef_joint_R1" type="fixed">
    <parent link="knee_R1"/>
    <child link="ef_R1"/>
    <origin rpy="0 0 0" xyz="0.0 -0.176295 0.0"/>
  </joint>
  <link name="ef_R1">
    <inertial>
      <origin rpy="0 0 0" xyz="0.0 0.0 0.0"/>
      <mass value="0.0"/>
      <inertia ixx="0.0" ixy="0.0" ixz="0.0" iyy="0.0" iyz="0.0" izz="0.0"/>
    </inertial>
  </link>
  <!-- Define actuators -->
  <transmission name="shoulder_transmission_R1">
    <type>transmission_interface/SimpleTransmission</type>
    <joint name="shoulder_joint_R1">
      <hardwareInterface>hardware_interface/EffortJointInterface</hardwareInterface>
    </joint>
    <actuator name="soulder_motor_R1">
      <hardwareInterface>hardware_interface/EffortJointInterface</hardwareInterface>
      <mechanicalReduction>1.0</mechanicalReduction>
      <motorTorqueConstant>1.0</motorTorqueConstant>
    </actuator>
  </transmission>
  <transmission name="hip_transmission_R1">
    <type>transmission_interface/SimpleTransmission</type>
    <joint name="hip_joint_R1">
      <hardwareInterface>hardware_interface/EffortJointInterface</hardwareInterface>
    </joint>
    <actuator name="hip_motor_R1">
      <hardwareInterface>hardware_interface/EffortJointInterface</hardwareInterface>
      <mechanicalReduction>1.0</mechanicalReduction>
      <motorTorqueConstant>1.0</motorTorqueConstant>
    </actuator>
  </transmission>
  <transmission name="knee_transmission_R1">
    <type>transmission_interface/SimpleTransmission</type>
    <joint name="knee_joint_R1">
      <hardwareInterface>hardware_interface/EffortJointInterface</hardwareInterface>
    </joint>
    <actuator name="knee_motor_R1">
      <hardwareInterface>hardware_interface/EffortJointInterface</hardwareInterface>
      <mechanicalReduction>1.0</mechanicalReduction>
      <motorTorqueConstant>1.0</motorTorqueConstant>
    </actuator>
  </transmission>
  <!-- Shoulder -->
  <joint name="shoulder_joint_L1" type="revolute">
    <parent link="torso"/>
    <child link="shoulder_L1"/>
    <origin rpy="3.141592653589793 -1.5707963267948966 0.0" xyz="0.1965 0.093 0"/>
    <axis xyz="0 0 -1"/>
    <dynamics damping="0.0" friction="0.0"/>
    <limit effort="2000" lower="2.6179938779914944" upper="-2.6179938779914944" velocity="0.05"/>
  </joint>
  <link name="shoulder_L1">
    <visual>
      <origin rpy="0 0 1.57" xyz="0 0 0"/>
      <geometry>
        <mesh filename="meshes/joint2.stl" scale="1 1 1"/>
      </geometry>
      <material name="white_blue"/>
    </visual>
    <collision>
      <origin rpy="0 0 1.57" xyz="0 0 0"/>
      <geometry>
        <mesh filename="meshes/joint2.stl" scale="1 1 1"/>
      </geometry>
    </collision>
    <inertial>
      <origin rpy="0 0 1.57" xyz="-2.2e-05 0.031173 0.057268"/>
      <mass value="0.733"/>
      <inertia ixx="0.00067621" ixy="3.8e-07" ixz="1.08e-07" iyy="0.000621118" iyz="-6.7409e-05" izz="0.000597825"/>
    </inertial>
    <contact>
      <lateral_friction value="1"/>
    </contact>
  </link>
  <!-- Hip-->
  <joint name="hip_joint_L1" type="revolute">
    <parent link="shoulder_L1"/>
    <child link="hip_L1"/>
    <origin rpy="0 -1.57 1.57" xyz="0 0.0025 0.060502"/>
    <axis xyz="0 0 -1"/>
    <dynamics damping="0.0" friction="0.0"/>
    <limit effort="2000" lower="2.6179938779914944" upper="-2.6179938779914944" velocity="0.05"/>
  </joint>
  <link name="hip_L1">
    <visual>
      <origin rpy="0 0 0" xyz="0 0 0"/>
      <geometry>
        <!-- <box size="0.202 0.05 0.03"/> -->
        <mesh filename="meshes/joint3.stl" scale="1 1 1"/>
      </geometry>
      <material name="silver"/>
    </visual>
    <collision>
      <geometry>
        <mesh filename="meshes/joint3.stl" scale="1 1 1"/>
      </geometry>
    </collision>
    <inertial>
      <origin rpy="0 0 0" xyz="0.022129 -0.00016 0.062823"/>
      <mass value="1.018"/>
      <inertia ixx="0.001081737" ixy="-2.78e-07" ixz="-0.000623088" iyy="0.003343252" iyz="-5e-07" izz="0.00299894"/>
    </inertial>
    <contact>
      <lateral_friction value="1"/>
    </contact>
  </link>
  <!-- Knee -->
  <joint name="knee_joint_L1" type="revolute">
    <parent link="hip_L1"/>
    <child link="knee_L1"/>
    <origin rpy="0 0 1.57" xyz="0.202 0 0.093"/>
    <axis xyz="0 0 -1"/>
    <dynamics damping="0.0" friction="0.0"/>
    <limit effort="2000" lower="-2.6179938779914944" upper="2.6179938779914944" velocity="0.05"/>
  </joint>
  <link name="knee_L1">
    <visual>
      <origin rpy="0 0 0" xyz="0 0 0"/>
      <geometry>
        <!-- <sphere radius="0.04"/> -->
        <mesh filename="meshes/joint4.stl" scale="1 1 1"/>
      </geometry>
      <material name="white_blue"/>
    </visual>
    <collision>
      <geometry>
        <mesh filename="meshes/joint4.stl" scale="1 1 1"/>
      </geometry>
    </collision>
    <inertial>
      <origin rpy="0 0 0" xyz="0.0 -0.055891 0.0"/>
      <mass value="0.195"/>
      <inertia ixx="0.000821112" ixy="0.0" ixz="0.0" iyy="3.9652e-05" iyz="0.0" izz="0.000838157"/>
    </inertial>
    <contact>
      <lateral_friction value="1"/>
    </contact>
  </link>
  <!-- End Effector-->
  <joint name="ef_joint_L1" type="fixed">
    <parent link="knee_L1"/>
    <child link="ef_L1"/>
    <origin rpy="0 0 0" xyz="0.0 -0.176295 0.0"/>
  </joint>
  <link name="ef_L1">
    <inertial>
      <origin rpy="0 0 0" xyz="0.0 0.0 0.0"/>
      <mass value="0.0"/>
      <inertia ixx="0.0" ixy="0.0" ixz="0.0" iyy="0.0" iyz="0.0" izz="0.0"/>
    </inertial>
  </link>
  <!-- Define actuators -->
  <transmission name="shoulder_transmission_L1">
    <type>transmission_interface/SimpleTransmission</type>
    <joint name="shoulder_joint_L1">
      <hardwareInterface>hardware_interface/EffortJointInterface</hardwareInterface>
    </joint>
    <actuator name="soulder_motor_L1">
      <hardwareInterface>hardware_interface/EffortJointInterface</hardwareInterface>
      <mechanicalReduction>1.0</mechanicalReduction>
      <motorTorqueConstant>1.0</motorTorqueConstant>
    </actuator>
  </transmission>
  <transmission name="hip_transmission_L1">
    <type>transmission_interface/SimpleTransmission</type>
    <joint name="hip_joint_L1">
      <hardwareInterface>hardware_interface/EffortJointInterface</hardwareInterface>
    </joint>
    <actuator name="hip_motor_L1">
      <hardwareInterface>hardware_interface/EffortJointInterface</hardwareInterface>
      <mechanicalReduction>1.0</mechanicalReduction>
      <motorTorqueConstant>1.0</motorTorqueConstant>
    </actuator>
  </transmission>
  <transmission name="knee_transmission_L1">
    <type>transmission_interface/SimpleTransmission</type>
    <joint name="knee_joint_L1">
      <hardwareInterface>hardware_interface/EffortJointInterface</hardwareInterface>
    </joint>
    <actuator name="knee_motor_L1">
      <hardwareInterface>hardware_interface/EffortJointInterface</hardwareInterface>
      <mechanicalReduction>1.0</mechanicalReduction>
      <motorTorqueConstant>1.0</motorTorqueConstant>
    </actuator>
  </transmission>
  <!-- Shoulder -->
  <joint name="shoulder_joint_R2" type="revolute">
    <parent link="torso"/>
    <child link="shoulder_R2"/>
    <origin rpy="0.0 -1.5707963267948966 0.0" xyz="-0.1965 -0.093 0"/>
    <axis xyz="0 0 -1"/>
    <dynamics damping="0.0" friction="0.0"/>
    <limit effort="2000" lower="2.6179938779914944" upper="-2.6179938779914944" velocity="0.05"/>
  </joint>
  <link name="shoulder_R2">
    <visual>
      <origin rpy="0 0 1.57" xyz="0 0 0"/>
      <geometry>
        <mesh filename="meshes/joint2.stl" scale="1 1 1"/>
      </geometry>
      <material name="white_blue"/>
    </visual>
    <collision>
      <origin rpy="0 0 1.57" xyz="0 0 0"/>
      <geometry>
        <mesh filename="meshes/joint2.stl" scale="1 1 1"/>
      </geometry>
    </collision>
    <inertial>
      <origin rpy="0 0 1.57" xyz="-2.2e-05 0.031173 0.057268"/>
      <mass value="0.733"/>
      <inertia ixx="0.00067621" ixy="3.8e-07" ixz="1.08e-07" iyy="0.000621118" iyz="-6.7409e-05" izz="0.000597825"/>
    </inertial>
    <contact>
      <lateral_friction value="1"/>
    </contact>
  </link>
  <!-- Hip-->
  <joint name="hip_joint_R2" type="revolute">
    <parent link="shoulder_R2"/>
    <child link="hip_R2"/>
    <origin rpy="0 -1.57 1.57" xyz="0 0.0025 0.060502"/>
    <axis xyz="0 0 -1"/>
    <dynamics damping="0.0" friction="0.0"/>
    <limit effort="2000" lower="2.6179938779914944" upper="-2.6179938779914944" velocity="0.05"/>
  </joint>
  <link name="hip_R2">
    <visual>
      <origin rpy="0 0 0" xyz="0 0 0"/>
      <geometry>
        <!-- <box size="0.202 0.05 0.03"/> -->
        <mesh filename="meshes/joint3.stl" scale="1 1 1"/>
      </geometry>
      <material name="silver"/>
    </visual>
    <collision>
      <geometry>
        <mesh filename="meshes/joint3.stl" scale="1 1 1"/>
      </geometry>
    </collision>
    <inertial>
      <origin rpy="0 0 0" xyz="0.022129 -0.00016 0.062823"/>
      <mass value="1.018"/>
      <inertia ixx="0.001081737" ixy="-2.78e-07" ixz="-0.000623088" iyy="0.003343252" iyz="-5e-07" izz="0.00299894"/>
    </inertial>
    <contact>
      <lateral_friction value="1"/>
    </contact>
  </link>
  <!-- Knee -->
  <joint name="knee_joint_R2" type="revolute">
    <parent link="hip_R2"/>
    <child link="knee_R2"/>
    <origin rpy="0 0 1.57" xyz="0.202 0 0.093"/>
    <axis xyz="0 0 -1"/>
    <dynamics damping="0.0" friction="0.0"/>
    <limit effort="2000" lower="-2.6179938779914944" upper="2.6179938779914944" velocity="0.05"/>
  </joint>
  <link name="knee_R2">
    <visual>
      <origin rpy="0 0 0" xyz="0 0 0"/>
      <geometry>
        <!-- <sphere radius="0.04"/> -->
        <mesh filename="meshes/joint4.stl" scale="1 1 1"/>
      </geometry>
      <material name="white_blue"/>
    </visual>
    <collision>
      <geometry>
        <mesh filename="meshes/joint4.stl" scale="1 1 1"/>
      </geometry>
    </collision>
    <inertial>
      <origin rpy="0 0 0" xyz="0.0 -0.055891 0.0"/>
      <mass value="0.195"/>
      <inertia ixx="0.000821112" ixy="0.0" ixz="0.0" iyy="3.9652e-05" iyz="0.0" izz="0.000838157"/>
    </inertial>
    <contact>
      <lateral_friction value="1"/>
    </contact>
  </link>
  <!-- End Effector-->
  <joint name="ef_joint_R2" type="fixed">
    <parent link="knee_R2"/>
    <child link="ef_R2"/>
    <origin rpy="0 0 0" xyz="0.0 -0.176295 0.0"/>
  </joint>
  <link name="ef_R2">
    <inertial>
      <origin rpy="0 0 0" xyz="0.0 0.0 0.0"/>
      <mass value="0.0"/>
      <inertia ixx="0.0" ixy="0.0" ixz="0.0" iyy="0.0" iyz="0.0" izz="0.0"/>
    </inertial>
  </link>
  <!-- Define actuators -->
  <transmission name="shoulder_transmission_R2">
    <type>transmission_interface/SimpleTransmission</type>
    <joint name="shoulder_joint_R2">
      <hardwareInterface>hardware_interface/EffortJointInterface</hardwareInterface>
    </joint>
    <actuator name="soulder_motor_R2">
      <hardwareInterface>hardware_interface/EffortJointInterface</hardwareInterface>
      <mechanicalReduction>1.0</mechanicalReduction>
      <motorTorqueConstant>1.0</motorTorqueConstant>
    </actuator>
  </transmission>
  <transmission name="hip_transmission_R2">
    <type>transmission_interface/SimpleTransmission</type>
    <joint name="hip_joint_R2">
      <hardwareInterface>hardware_interface/EffortJointInterface</hardwareInterface>
    </joint>
    <actuator name="hip_motor_R2">
      <hardwareInterface>hardware_interface/EffortJointInterface</hardwareInterface>
      <mechanicalReduction>1.0</mechanicalReduction>
      <motorTorqueConstant>1.0</motorTorqueConstant>
    </actuator>
  </transmission>
  <transmission name="knee_transmission_R2">
    <type>transmission_interface/SimpleTransmission</type>
    <joint name="knee_joint_R2">
      <hardwareInterface>hardware_interface/EffortJointInterface</hardwareInterface>
    </joint>
    <actuator name="knee_motor_R2">
      <hardwareInterface>hardware_interface/EffortJointInterface</hardwareInterface>
      <mechanicalReduction>1.0</mechanicalReduction>
      <motorTorqueConstant>1.0</motorTorqueConstant>
    </actuator>
  </transmission>
  <!-- Shoulder -->
  <joint name="shoulder_joint_L2" type="revolute">
    <parent link="torso"/>
    <child link="shoulder_L2"/>
    <origin rpy="3.141592653589793 1.5707963267948966 0.0" xyz="-0.1965 0.093 0"/>
    <axis xyz="0 0 -1"/>
    <dynamics damping="0.0" friction="0.0"/>
    <limit effort="2000" lower="2.6179938779914944" upper="-2.6179938779914944" velocity="0.05"/>
  </joint>
  <link name="shoulder_L2">
    <visual>
      <origin rpy="0 0 1.57" xyz="0 0 0"/>
      <geometry>
        <mesh filename="meshes/joint2.stl" scale="1 1 1"/>
      </geometry>
      <material name="white_blue"/>
    </visual>
    <collision>
      <origin rpy="0 0 1.57" xyz="0 0 0"/>
      <geometry>
        <mesh filename="meshes/joint2.stl" scale="1 1 1"/>
      </geometry>
    </collision>
    <inertial>
      <origin rpy="0 0 1.57" xyz="-2.2e-05 0.031173 0.057268"/>
      <mass value="0.733"/>
      <inertia ixx="0.00067621" ixy="3.8e-07" ixz="1.08e-07" iyy="0.000621118" iyz="-6.7409e-05" izz="0.000597825"/>
    </inertial>
    <contact>
      <lateral_friction value="1"/>
    </contact>
  </link>
  <!-- Hip-->
  <joint name="hip_joint_L2" type="revolute">
    <parent link="shoulder_L2"/>
    <child link="hip_L2"/>
    <origin rpy="0 -1.57 1.57" xyz="0 0.0025 0.060502"/>
    <axis xyz="0 0 -1"/>
    <dynamics damping="0.0" friction="0.0"/>
    <limit effort="2000" lower="2.6179938779914944" upper="-2.6179938779914944" velocity="0.05"/>
  </joint>
  <link name="hip_L2">
    <visual>
      <origin rpy="0 0 0" xyz="0 0 0"/>
      <geometry>
        <!-- <box size="0.202 0.05 0.03"/> -->
        <mesh filename="meshes/joint3.stl" scale="1 1 1"/>
      </geometry>
      <material name="silver"/>
    </visual>
    <collision>
      <geometry>
        <mesh filename="meshes/joint3.stl" scale="1 1 1"/>
      </geometry>
    </collision>
    <inertial>
      <origin rpy="0 0 0" xyz="0.022129 -0.00016 0.062823"/>
      <mass value="1.018"/>
      <inertia ixx="0.001081737" ixy="-2.78e-07" ixz="-0.000623088" iyy="0.003343252" iyz="-5e-07" izz="0.00299894"/>
    </inertial>
    <contact>
      <lateral_friction value="1"/>
    </contact>
  </link>
  <!-- Knee -->
  <joint name="knee_joint_L2" type="revolute">
    <parent link="hip_L2"/>
    <child link="knee_L2"/>
    <origin rpy="0 0 1.57" xyz="0.202 0 0.093"/>
    <axis xyz="0 0 -1"/>
    <dynamics damping="0.0" friction="0.0"/>
    <limit effort="2000" lower="-2.6179938779914944" upper="2.6179938779914944" velocity="0.05"/>
  </joint>
  <link name="knee_L2">
    <visual>
      <origin rpy="0 0 0" xyz="0 0 0"/>
      <geometry>
        <!-- <sphere radius="0.04"/> -->
        <mesh filename="meshes/joint4.stl" scale="1 1 1"/>
      </geometry>
      <material name="white_blue"/>
    </visual>
    <collision>
      <geometry>
        <mesh filename="meshes/joint4.stl" scale="1 1 1"/>
      </geometry>
    </collision>
    <inertial>
      <origin rpy="0 0 0" xyz="0.0 -0.055891 0.0"/>
      <mass value="0.195"/>
      <inertia ixx="0.000821112" ixy="0.0" ixz="0.0" iyy="3.9652e-05" iyz="0.0" izz="0.000838157"/>
    </inertial>
    <contact>
      <lateral_friction value="1"/>
    </contact>
  </link>
  <!-- End Effector-->
  <joint name="ef_joint_L2" type="fixed">
    <parent link="knee_L2"/>
    <child link="ef_L2"/>
    <origin rpy="0 0 0" xyz="0.0 -0.176295 0.0"/>
  </joint>
  <link name="ef_L2">
    <inertial>
      <origin rpy="0 0 0" xyz="0.0 0.0 0.0"/>
      <mass value="0.0"/>
      <inertia ixx="0.0" ixy="0.0" ixz="0.0" iyy="0.0" iyz="0.0" izz="0.0"/>
    </inertial>
  </link>
  <!-- Define actuators -->
  <transmission name="shoulder_transmission_L2">
    <type>transmission_interface/SimpleTransmission</type>
    <joint name="shoulder_joint_L2">
      <hardwareInterface>hardware_interface/EffortJointInterface</hardwareInterface>
    </joint>
    <actuator name="soulder_motor_L2">
      <hardwareInterface>hardware_interface/EffortJointInterface</hardwareInterface>
      <mechanicalReduction>1.0</mechanicalReduction>
      <motorTorqueConstant>1.0</motorTorqueConstant>
    </actuator>
  </transmission>
  <transmission name="hip_transmission_L2">
    <type>transmission_interface/SimpleTransmission</type>
    <joint name="hip_joint_L2">
      <hardwareInterface>hardware_interface/EffortJointInterface</hardwareInterface>
    </joint>
    <actuator name="hip_motor_L2">
      <hardwareInterface>hardware_interface/EffortJointInterface</hardwareInterface>
      <mechanicalReduction>1.0</mechanicalReduction>
      <motorTorqueConstant>1.0</motorTorqueConstant>
    </actuator>
  </transmission>
  <transmission name="knee_transmission_L2">
    <type>transmission_interface/SimpleTransmission</type>
    <joint name="knee_joint_L2">
      <hardwareInterface>hardware_interface/EffortJointInterface</hardwareInterface>
    </joint>
    <actuator name="knee_motor_L2">
      <hardwareInterface>hardware_interface/EffortJointInterface</hardwareInterface>
      <mechanicalReduction>1.0</mechanicalReduction>
      <motorTorqueConstant>1.0</motorTorqueConstant>
    </actuator>
  </transmission>
</robot>

